test_01 (__main__.TestDemo) ... ok
test_02 (__main__.TestDemo) ... FAIL

======================================================================
FAIL: test_02 (__main__.TestDemo)
----------------------------------------------------------------------
Traceback (most recent call last):
  File "c:\workhome\HttpTest\test_demo.py", line 17, in test_02
    self.assertEqual(1,2)
AssertionError: 1 != 2

----------------------------------------------------------------------
Ran 2 tests in 0.009s

FAILED (failures=1)
