test_01 (__main__.TestDemo) ... ok
test_02 (__main__.TestDemo) ... ok
test_03 (__main__.TestDemo) ... FAIL

======================================================================
FAIL: test_03 (__main__.TestDemo)
----------------------------------------------------------------------
Traceback (most recent call last):
  File "f:\MyPython\MuKeWang\test.py", line 20, in test_03
    self.assertEqual(a*b,5)
AssertionError: 6 != 5

----------------------------------------------------------------------
Ran 3 tests in 0.004s

FAILED (failures=1)
